2019-12-14 11:56:00,444 ERROR: Exception on /index [GET] [in /Users/vish/Projects/flask_tutorial/microblog/env/lib/python3.7/site-packages/flask/app.py:1891]
Traceback (most recent call last):
  File "/Users/vish/Projects/flask_tutorial/microblog/env/lib/python3.7/site-packages/flask/app.py", line 2446, in wsgi_app
    response = self.full_dispatch_request()
  File "/Users/vish/Projects/flask_tutorial/microblog/env/lib/python3.7/site-packages/flask/app.py", line 1951, in full_dispatch_request
    rv = self.handle_user_exception(e)
  File "/Users/vish/Projects/flask_tutorial/microblog/env/lib/python3.7/site-packages/flask/app.py", line 1820, in handle_user_exception
    reraise(exc_type, exc_value, tb)
  File "/Users/vish/Projects/flask_tutorial/microblog/env/lib/python3.7/site-packages/flask/_compat.py", line 39, in reraise
    raise value
  File "/Users/vish/Projects/flask_tutorial/microblog/env/lib/python3.7/site-packages/flask/app.py", line 1947, in full_dispatch_request
    rv = self.preprocess_request()
  File "/Users/vish/Projects/flask_tutorial/microblog/env/lib/python3.7/site-packages/flask/app.py", line 2241, in preprocess_request
    rv = func()
  File "/Users/vish/Projects/flask_tutorial/microblog/app/routes.py", line 11, in before_request
    if current_user.is_authenticated:
  File "/Users/vish/Projects/flask_tutorial/microblog/env/lib/python3.7/site-packages/werkzeug/local.py", line 348, in __getattr__
    return getattr(self._get_current_object(), name)
  File "/Users/vish/Projects/flask_tutorial/microblog/env/lib/python3.7/site-packages/werkzeug/local.py", line 307, in _get_current_object
    return self.__local()
  File "/Users/vish/Projects/flask_tutorial/microblog/env/lib/python3.7/site-packages/flask_login/utils.py", line 26, in <lambda>
    current_user = LocalProxy(lambda: _get_user())
  File "/Users/vish/Projects/flask_tutorial/microblog/env/lib/python3.7/site-packages/flask_login/utils.py", line 335, in _get_user
    current_app.login_manager._load_user()
  File "/Users/vish/Projects/flask_tutorial/microblog/env/lib/python3.7/site-packages/flask_login/login_manager.py", line 359, in _load_user
    return self.reload_user()
  File "/Users/vish/Projects/flask_tutorial/microblog/env/lib/python3.7/site-packages/flask_login/login_manager.py", line 317, in reload_user
    "No user_loader has been installed for this "
Exception: No user_loader has been installed for this LoginManager. Refer tohttps://flask-login.readthedocs.io/en/latest/#how-it-works for more info.
2019-12-14 11:56:08,340 INFO: Microblog startup [in /Users/vish/Projects/flask_tutorial/microblog/app/__init__.py:44]
2019-12-14 11:56:08,684 INFO: Microblog startup [in /Users/vish/Projects/flask_tutorial/microblog/app/__init__.py:44]
2019-12-14 11:56:10,936 ERROR: Exception on /index [GET] [in /Users/vish/Projects/flask_tutorial/microblog/env/lib/python3.7/site-packages/flask/app.py:1891]
Traceback (most recent call last):
  File "/Users/vish/Projects/flask_tutorial/microblog/env/lib/python3.7/site-packages/sqlalchemy/engine/base.py", line 1246, in _execute_context
    cursor, statement, parameters, context
  File "/Users/vish/Projects/flask_tutorial/microblog/env/lib/python3.7/site-packages/sqlalchemy/engine/default.py", line 581, in do_execute
    cursor.execute(statement, parameters)
sqlite3.OperationalError: no such table: user

The above exception was the direct cause of the following exception:

Traceback (most recent call last):
  File "/Users/vish/Projects/flask_tutorial/microblog/env/lib/python3.7/site-packages/flask/app.py", line 2446, in wsgi_app
    response = self.full_dispatch_request()
  File "/Users/vish/Projects/flask_tutorial/microblog/env/lib/python3.7/site-packages/flask/app.py", line 1951, in full_dispatch_request
    rv = self.handle_user_exception(e)
  File "/Users/vish/Projects/flask_tutorial/microblog/env/lib/python3.7/site-packages/flask/app.py", line 1820, in handle_user_exception
    reraise(exc_type, exc_value, tb)
  File "/Users/vish/Projects/flask_tutorial/microblog/env/lib/python3.7/site-packages/flask/_compat.py", line 39, in reraise
    raise value
  File "/Users/vish/Projects/flask_tutorial/microblog/env/lib/python3.7/site-packages/flask/app.py", line 1947, in full_dispatch_request
    rv = self.preprocess_request()
  File "/Users/vish/Projects/flask_tutorial/microblog/env/lib/python3.7/site-packages/flask/app.py", line 2241, in preprocess_request
    rv = func()
  File "/Users/vish/Projects/flask_tutorial/microblog/app/routes.py", line 11, in before_request
    if current_user.is_authenticated:
  File "/Users/vish/Projects/flask_tutorial/microblog/env/lib/python3.7/site-packages/werkzeug/local.py", line 348, in __getattr__
    return getattr(self._get_current_object(), name)
  File "/Users/vish/Projects/flask_tutorial/microblog/env/lib/python3.7/site-packages/werkzeug/local.py", line 307, in _get_current_object
    return self.__local()
  File "/Users/vish/Projects/flask_tutorial/microblog/env/lib/python3.7/site-packages/flask_login/utils.py", line 26, in <lambda>
    current_user = LocalProxy(lambda: _get_user())
  File "/Users/vish/Projects/flask_tutorial/microblog/env/lib/python3.7/site-packages/flask_login/utils.py", line 335, in _get_user
    current_app.login_manager._load_user()
  File "/Users/vish/Projects/flask_tutorial/microblog/env/lib/python3.7/site-packages/flask_login/login_manager.py", line 359, in _load_user
    return self.reload_user()
  File "/Users/vish/Projects/flask_tutorial/microblog/env/lib/python3.7/site-packages/flask_login/login_manager.py", line 321, in reload_user
    user = self.user_callback(user_id)
  File "/Users/vish/Projects/flask_tutorial/microblog/app/models.py", line 9, in load_user
    return User.query.get(int(id))
  File "/Users/vish/Projects/flask_tutorial/microblog/env/lib/python3.7/site-packages/sqlalchemy/orm/query.py", line 982, in get
    return self._get_impl(ident, loading.load_on_pk_identity)
  File "/Users/vish/Projects/flask_tutorial/microblog/env/lib/python3.7/site-packages/sqlalchemy/orm/query.py", line 1094, in _get_impl
    return db_load_fn(self, primary_key_identity)
  File "/Users/vish/Projects/flask_tutorial/microblog/env/lib/python3.7/site-packages/sqlalchemy/orm/loading.py", line 284, in load_on_pk_identity
    return q.one()
  File "/Users/vish/Projects/flask_tutorial/microblog/env/lib/python3.7/site-packages/sqlalchemy/orm/query.py", line 3325, in one
    ret = self.one_or_none()
  File "/Users/vish/Projects/flask_tutorial/microblog/env/lib/python3.7/site-packages/sqlalchemy/orm/query.py", line 3294, in one_or_none
    ret = list(self)
  File "/Users/vish/Projects/flask_tutorial/microblog/env/lib/python3.7/site-packages/sqlalchemy/orm/query.py", line 3367, in __iter__
    return self._execute_and_instances(context)
  File "/Users/vish/Projects/flask_tutorial/microblog/env/lib/python3.7/site-packages/sqlalchemy/orm/query.py", line 3392, in _execute_and_instances
    result = conn.execute(querycontext.statement, self._params)
  File "/Users/vish/Projects/flask_tutorial/microblog/env/lib/python3.7/site-packages/sqlalchemy/engine/base.py", line 982, in execute
    return meth(self, multiparams, params)
  File "/Users/vish/Projects/flask_tutorial/microblog/env/lib/python3.7/site-packages/sqlalchemy/sql/elements.py", line 287, in _execute_on_connection
    return connection._execute_clauseelement(self, multiparams, params)
  File "/Users/vish/Projects/flask_tutorial/microblog/env/lib/python3.7/site-packages/sqlalchemy/engine/base.py", line 1101, in _execute_clauseelement
    distilled_params,
  File "/Users/vish/Projects/flask_tutorial/microblog/env/lib/python3.7/site-packages/sqlalchemy/engine/base.py", line 1250, in _execute_context
    e, statement, parameters, cursor, context
  File "/Users/vish/Projects/flask_tutorial/microblog/env/lib/python3.7/site-packages/sqlalchemy/engine/base.py", line 1476, in _handle_dbapi_exception
    util.raise_from_cause(sqlalchemy_exception, exc_info)
  File "/Users/vish/Projects/flask_tutorial/microblog/env/lib/python3.7/site-packages/sqlalchemy/util/compat.py", line 398, in raise_from_cause
    reraise(type(exception), exception, tb=exc_tb, cause=cause)
  File "/Users/vish/Projects/flask_tutorial/microblog/env/lib/python3.7/site-packages/sqlalchemy/util/compat.py", line 152, in reraise
    raise value.with_traceback(tb)
  File "/Users/vish/Projects/flask_tutorial/microblog/env/lib/python3.7/site-packages/sqlalchemy/engine/base.py", line 1246, in _execute_context
    cursor, statement, parameters, context
  File "/Users/vish/Projects/flask_tutorial/microblog/env/lib/python3.7/site-packages/sqlalchemy/engine/default.py", line 581, in do_execute
    cursor.execute(statement, parameters)
sqlalchemy.exc.OperationalError: (sqlite3.OperationalError) no such table: user
[SQL: SELECT user.id AS user_id, user.username AS user_username, user.email AS user_email, user.password_hash AS user_password_hash, user.about_me AS user_about_me, user.last_seen AS user_last_seen 
FROM user 
WHERE user.id = ?]
[parameters: (1,)]
(Background on this error at: http://sqlalche.me/e/e3q8)
2019-12-14 11:56:32,044 INFO: Microblog startup [in /Users/vish/Projects/flask_tutorial/microblog/app/__init__.py:44]
2019-12-14 11:56:32,392 INFO: Microblog startup [in /Users/vish/Projects/flask_tutorial/microblog/app/__init__.py:44]
